Workbook
Name A1.: 'Datos personales'!$RAA$1892
Name A1.: #REF!
Name aranceles: #REF!
Name aranceles: #REF!
Name inscripciones: #REF!
Name inscripciones: #REF!
Name IVA: #REF!
Name IVA: #REF!
Name materias: #REF!
Name materias: #REF!
Name Productos: #REF!
Name Productos: #REF!
Name SegmentaciónDeDatos_Cilindrada__cc_: #N/A
Name SegmentaciónDeDatos_Precio: #N/A
Name SegmentaciónDeDatos_Producto: #N/A
Name SegmentaciónDeDatos_Sucursal: #N/A
Name VER: #REF!

Sheet Datos personales
A1: Apellido y Nombre, Curso y Docente/s
A2: Ejemplo | B2: Juan Cruz Mamerto Garcia, 912-36, Armando Balcarce
A3: Luciano Gabriel Escalante, 912-1939, Sosa Omar
RAH1900: Empezo a trabajar con el Ejercicio 2 el
RAH1901: =IF(RAH1901=0,IF('Ejercicio 2'!F3=0,0,TEXT(NOW(),"dd/mm/aaaa")&" a las "&TEXT(NOW(),"hh:mm:ss")),RAH1901) -> 19/02/2026 a las 18:54:12
RAG1903: =IF(A3=RAI1904,RAG1903,NOW()) -> 46072.776 | RAH1903: Cambios de autor del archivo | RAI1903: Dato Anterior
RAH1904: =IF(RAG1903=0,"-",IF(A3=RAI1904,RAH1904,RAH1904&"👉 "&TEXT(RAG1903,"dd/mm/aaaa hh:mm:ss")&".-- "&" --> "&"("&A3&")")) -> 0👉 19/02/2026 18:37:12.-- --> (Luciano Gabriel Escalante, )👉 19/02/2026 18:37:24.-- --> (Luciano Gabriel Escalante, 912-1939, Sosa Omar) | RAI1904: =IF(A3=RAI1904,RAI1904,A3) -> Luciano Gabriel Escalante, 912-1939, Sosa Omar

Sheet Ejercicio 1
A3: VENDEDOR | B3: CLIENTE | C3: FECHA | D3: DIA VENTA | E3: PRODUCTO | F3: CANTIDAD | G3: IMPORTE
A4: JORGE ORTIZ | B4: MC LONG | C4: 42858 | D4: VIE | E4: TR45 | F4: 12 | G4: 5200
A5: JORGE ORTIZ | B5: LOPEZ | C5: 42859 | D5: SAB | E5: VT67 | F5: 23 | G5: 6400
A6: LUIS NUÑEZ | B6: SMITH | C6: 42860 | D6: DOM | E6: SW23 | F6: 12 | G6: 2600
A7: LUIS NUÑEZ | B7: SMITH | C7: 42860 | D7: DOM | E7: SW26 | F7: 32 | G7: 1500
A8: JORGE ORTIZ | B8: GOMEZ | C8: 42860 | D8: DOM | E8: TR45 | F8: 43 | G8: 2700
A9: JORGE ORTIZ | B9: MC LONG | C9: 42865 | D9: VIE | E9: SM26 | F9: 44 | G9: 3400
A10: ANA DIAZ | B10: RODRIGUEZ | C10: 42871 | D10: JUE | E10: TR45 | F10: 33 | G10: 6500
A11: ANA DIAZ | B11: PEREZ | C11: 42867 | D11: DOM | E11: SM26 | F11: 26 | G11: 8600
A12: LUIS NUÑEZ | B12: SMITH | C12: 42860 | D12: DOM | E12: SW26 | F12: 29 | G12: 3100
A13: LUIS NUÑEZ | B13: SMITH | C13: 42863 | D13: MIE | E13: SW23 | F13: 12 | G13: 3700
A14: JORGE ORTIZ | B14: MC LONG | C14: 42863 | D14: MIE | E14: VT12 | F14: 54 | G14: 1500
A15: JORGE ORTIZ | B15: MC LONG | C15: 42865 | D15: VIE | E15: SM26 | F15: 32 | G15: 2640
... A28: JORGE ORTIZ | B28: MC LONG | C28: 42872 | D28: VIE | E28: VT12 | F28: 12 | G28: 17925
A30: Suma de CANTIDAD | C30: PRODUCTO
A31: VENDEDOR | B31: FECHA | C31: SM26 | D31: SW23 | E31: SW26 | F31: TR45 | G31: VT12 | H31: VT67 | I31: Total general
A32: ANA DIAZ | B32: 42867 | C32: 26 | D32: 43 | I32: 69
B33: 42871 | F33: 60 | I33: 60
A34: Total ANA DIAZ | C34: 26 | D34: 43 | F34: 60 | I34: 129
A35: JORGE ORTIZ | B35: 42858 | F35: 12 | I35: 12
B36: 42859 | H36: 23 | I36: 23
B37: 42860 | F37: 43 | I37: 43
B38: 42863 | G38: 54 | I38: 54
B39: 42865 | C39: 76 | F39: 22 | I39: 98
B40: 42867 | F40: 23 | I40: 23
B41: 42868 | E41: 34 | F41: 45 | I41: 79
B42: 42870 | D42: 34 | E42: 23 | I42: 57
B43: 42872 | G43: 12 | I43: 12
B44: 42875 | G44: 33 | I44: 33
A45: Total JORGE ORTIZ | C45: 76 | D45: 34 | E45: 57 | F45: 145 | G45: 99 | H45: 23 | I45: 434
A46: LUIS NUÑEZ | B46: 42860 | D46: 12 | E46: 61 | I46: 73
B47: 42863 | D47: 24 | I47: 24
B48: 42868 | F48: 130 | I48: 130
A49: Total LUIS NUÑEZ | D49: 36 | E49: 61 | F49: 130 | I49: 227
A50: Total general | C50: 102 | D50: 113 | E50: 118 | F50: 335 | G50: 99 | H50: 23 | I50: 790
A53: FECHA | B53: (Todas)
A55: VENDEDOR | B55: CLIENTE | C55: Suma de IMPORTE
A56: ANA DIAZ | B56: PEREZ | C56: 8600
B57: RODRIGUEZ | C57: 14474
A58: Total ANA DIAZ | C58: 23074
...

Sheet Ejercicio 2
C1: CINE POPULAR BARRIAL | M1: CTII-2024
A2: CODIGO | B2: PELICULA | C2: GENERO | D2: CATEGORIA | E2: LOCALIDADES VENDIDAS | F2: PRECIO LOCALIDADES
A3: 1 | B3: Lo que el viento se llevó | C3: Clásica | D3: ATP | E3: 22 | F3: =VLOOKUP(D3,$A$61:$B$65,2,0) -> 35
A4: 2 | B4: Casa Blanca | C4: Clásica | D4: ATP | E4: 27 | F4: =VLOOKUP(D4,$A$61:$B$65,2,0) -> 35
A5: 3 | B5: Blancanieves | C5: Infantil | D5: ATP | E5: 35 | F5: =VLOOKUP(D5,$A$61:$B$65,2,0) -> 35
A6: 4 | B6: 2001 Odisea del espacio | C6: C.Ficción | D6: PM16 | E6: 40 | F6: =VLOOKUP(D6,$A$61:$B$65,2,0) -> 42
A7: 5 | B7: La guerra de las galaxias | C7: C.Ficción | D7: ATP | E7: 45 | F7: =VLOOKUP(D7,$A$61:$B$65,2,0) -> 35
A8: 6 | B8: Robocop | C8: C.Ficción | D8: ATP | E8: 50 | F8: =VLOOKUP(D8,$A$61:$B$65,2,0) -> 35
A9: 7 | B9: Robocop 2 | C9: C.Ficción | D9: ATP | E9: 52 | F9: =VLOOKUP(D9,$A$61:$B$65,2,0) -> 35
A10: 8 | B10: Matrix | C10: C.Ficción | D10: ATP | E10: 70 | F10: =VLOOKUP(D10,$A$61:$B$65,2,0) -> 35
A11: 9 | B11: Matrix 2 | C11: C.Ficción | D11: ATP | E11: 70 | F11: =VLOOKUP(D11,$A$61:$B$65,2,0) -> 35
A12: 10 | B12: Matrix 3 | C12: C.Ficción | D12: ATP | E12: 55 | F12: =VLOOKUP(D12,$A$61:$B$65,2,0) -> 35
A13: 11 | B13: Rocky 1 | C13: Acción | D13: PM13 | E13: 70 | F13: =VLOOKUP(D13,$A$61:$B$65,2,0) -> 39
A14: 12 | B14: Rocky 2 | C14: Acción | D14: PM13 | E14: 72 | F14: =VLOOKUP(D14,$A$61:$B$65,2,0) -> 39
... A56: 54 | B56: Copycat | C56: Suspenso | D56: PM13 | E56: 30 | F56: =VLOOKUP(D56,$A$61:$B$65,2,0) -> 39
A61: Categoría | B61: Precio Localidades
A62: ATP | B62: 35
A63: PM13 | B63: 39
A64: PM16 | B64: 42
A65: PM18 | B65: 45
A71: 2.a | B71: CRITERIO | C71: CODIGO | D71: PELICULA | E71: GENERO | F71: CATEGORIA | G71: PRECIO LOCALIDADES
D72: Matrix 3
B73: Resultado: | C73: La pelicula es genero: | E73: =DGET('Ejercicio 2 .1'!A2:F56,'Ejercicio 2 .1'!C2,D71:D72) -> C.Ficción
A76: 2.b | B76: CRITERIO | C76: CODIGO | D76: PELICULA | E76: GENERO | F76: CATEGORIA | G76: PRECIO LOCALIDADES
E77: Drama | F77: PM13
B78: Resultado: | C78: La cantidad de peliculas es: | E78: =DCOUNTA('Ejercicio 2 .1'!A2:F56,'Ejercicio 2 .1'!A2,E76:F77) -> 3
A81: 2.c | B81: CRITERIO | C81: CODIGO | D81: PELICULA | E81: GENERO | F81: CATEGORIA | G81: PRECIO LOCALIDADES
E82: Acción
E83: Suspenso
B84: Resultado: | C84: Total de localidades vendidas | E84: =DSUM('Ejercicio 2 .1'!A2:F56,'Ejercicio 2 .1'!E2,E81:E83) -> 477
A100: 41730

Sheet Ejercicio 2 .1
C1: CINE POPULAR BARRIAL | M1: CTII-2024
A2: CODIGO | B2: PELICULA | C2: GENERO | D2: CATEGORIA | E2: LOCALIDADES VENDIDAS | F2: PRECIO LOCALIDADES
A3: 1 | B3: Lo que el viento se llevó | C3: Clásica | D3: ATP | E3: 22 | F3: =VLOOKUP(D3,$A$61:$B$65,2,0) -> 35
A4: 2 | B4: Casa Blanca | C4: Clásica | D4: ATP | E4: 27 | F4: =VLOOKUP(D4,$A$61:$B$65,2,0) -> 35
A5: 3 | B5: Blancanieves | C5: Infantil | D5: ATP | E5: 35 | F5: =VLOOKUP(D5,$A$61:$B$65,2,0) -> 35
A6: 4 | B6: 2001 Odisea del espacio | C6: C.Ficción | D6: PM16 | E6: 40 | F6: =VLOOKUP(D6,$A$61:$B$65,2,0) -> 42
A7: 5 | B7: La guerra de las galaxias | C7: C.Ficción | D7: ATP | E7: 45 | F7: =VLOOKUP(D7,$A$61:$B$65,2,0) -> 35
A8: 6 | B8: Robocop | C8: C.Ficción | D8: ATP | E8: 50 | F8: =VLOOKUP(D8,$A$61:$B$65,2,0) -> 35
A9: 7 | B9: Robocop 2 | C9: C.Ficción | D9: ATP | E9: 52 | F9: =VLOOKUP(D9,$A$61:$B$65,2,0) -> 35
A10: 8 | B10: Matrix | C10: C.Ficción | D10: ATP | E10: 70 | F10: =VLOOKUP(D10,$A$61:$B$65,2,0) -> 35
A11: 9 | B11: Matrix 2 | C11: C.Ficción | D11: ATP | E11: 70 | F11: =VLOOKUP(D11,$A$61:$B$65,2,0) -> 35
A12: 10 | B12: Matrix 3 | C12: C.Ficción | D12: ATP | E12: 55 | F12: =VLOOKUP(D12,$A$61:$B$65,2,0) -> 35
A13: 11 | B13: Rocky 1 | C13: Acción | D13: PM13 | E13: 70 | F13: =VLOOKUP(D13,$A$61:$B$65,2,0) -> 39
A14: 12 | B14: Rocky 2 | C14: Acción | D14: PM13 | E14: 72 | F14: =VLOOKUP(D14,$A$61:$B$65,2,0) -> 39
... A56: 54 | B56: Copycat | C56: Suspenso | D56: PM13 | E56: 30 | F56: =VLOOKUP(D56,$A$61:$B$65,2,0) -> 39
A61: Categoría | B61: Precio Localidades
A62: ATP | B62: 35
A63: PM13 | B63: 39
A64: PM16 | B64: 42
A65: PM18 | B65: 45
A69: A) | B69: CODIGO | C69: PELICULA | D69: GENERO | E69: CATEGORIA | F69: LOCALIDADES VENDIDAS | G69: PRECIO LOCALIDADES
B70: 18 | C70: ET | D70: C.Ficción | E70: PM13 | F70: 50 | G70: =VLOOKUP(E70,'Ejercicio 2 .2'!$A$61:$B$65,2,0) -> 39
B71: 29 | C71: Time Cop | D71: C.Ficción | E71: PM13 | F71: 34 | G71: =VLOOKUP(E71,'Ejercicio 2 .2'!$A$61:$B$65,2,0) -> 39
B72: 53 | C72: 2010 el año que... | D72: C.Ficción | E72: PM13 | F72: 34 | G72: =VLOOKUP(E72,'Ejercicio 2 .2'!$A$61:$B$65,2,0) -> 39
A75: B) | B75: CODIGO | C75: PELICULA | D75: GENERO | E75: CATEGORIA | F75: LOCALIDADES VENDIDAS | G75: PRECIO LOCALIDADES
B76: 8 | C76: Matrix | D76: C.Ficción | E76: ATP | F76: 70 | G76: =VLOOKUP(E76,'Ejercicio 2 .2'!$A$61:$B$65,2,0) -> 35
B77: 9 | C77: Matrix 2 | D77: C.Ficción | E77: ATP | F77: 70 | G77: =VLOOKUP(E77,'Ejercicio 2 .2'!$A$61:$B$65,2,0) -> 35
B78: 10 | C78: Matrix 3 | D78: C.Ficción | E78: ATP | F78: 55 | G78: =VLOOKUP(E78,'Ejercicio 2 .2'!$A$61:$B$65,2,0) -> 35
B79: 45 | C79: Mi pie izquierdo | D79: Drama | E79: PM13 | F79: 50 | G79: =VLOOKUP(E79,'Ejercicio 2 .2'!$A$61:$B$65,2,0) -> 39
B80: 47 | C80: Mi vida | D80: Drama | E80: PM13 | F80: 43 | G80: =VLOOKUP(E80,'Ejercicio 2 .2'!$A$61:$B$65,2,0) -> 39
A83: C) | B83: CODIGO | C83: PELICULA | D83: GENERO | E83: CATEGORIA | F83: LOCALIDADES VENDIDAS | G83: PRECIO LOCALIDADES
B84: 22 | C84: La mano que... | D84: Suspenso | E84: PM18 | F84: 12 | G84: =VLOOKUP(E84,'Ejercicio 2 .2'!$A$61:$B$65,2,0) -> 45
B85: 33 | C85: Atracción fatal | D85: Suspenso | E85: PM18 | F85: 54 | G85: =VLOOKUP(E85,'Ejercicio 2 .2'!$A$61:$B$65,2,0) -> 45
A101: 41730

Sheet Ejercicio 2 .2
C1: CINE POPULAR BARRIAL | M1: CTII-2024
A2: CODIGO | B2: PELICULA | C2: GENERO | D2: CATEGORIA | E2: LOCALIDADES VENDIDAS | F2: PRECIO LOCALIDADES
A3: 1 | B3: Lo que el viento se llevó | C3: Clásica | D3: ATP | E3: 22 | F3: =VLOOKUP(D3,$A$61:$B$65,2,0) -> 35
A4: 2 | B4: Casa Blanca | C4: Clásica | D4: ATP | E4: 27 | F4: =VLOOKUP(D4,$A$61:$B$65,2,0) -> 35
A5: 3 | B5: Blancanieves | C5: Infantil | D5: ATP | E5: 35 | F5: =VLOOKUP(D5,$A$61:$B$65,2,0) -> 35
A6: 4 | B6: 2001 Odisea del espacio | C6: C.Ficción | D6: PM16 | E6: 40 | F6: =VLOOKUP(D6,$A$61:$B$65,2,0) -> 42
A7: 5 | B7: La guerra de las galaxias | C7: C.Ficción | D7: ATP | E7: 45 | F7: =VLOOKUP(D7,$A$61:$B$65,2,0) -> 35
A8: 6 | B8: Robocop | C8: C.Ficción | D8: ATP | E8: 50 | F8: =VLOOKUP(D8,$A$61:$B$65,2,0) -> 35
A9: 7 | B9: Robocop 2 | C9: C.Ficción | D9: ATP | E9: 52 | F9: =VLOOKUP(D9,$A$61:$B$65,2,0) -> 35
A10: 8 | B10: Matrix | C10: C.Ficción | D10: ATP | E10: 70 | F10: =VLOOKUP(D10,$A$61:$B$65,2,0) -> 35
A11: 9 | B11: Matrix 2 | C11: C.Ficción | D11: ATP | E11: 70 | F11: =VLOOKUP(D11,$A$61:$B$65,2,0) -> 35
A12: 10 | B12: Matrix 3 | C12: C.Ficción | D12: ATP | E12: 55 | F12: =VLOOKUP(D12,$A$61:$B$65,2,0) -> 35
A13: 11 | B13: Rocky 1 | C13: Acción | D13: PM13 | E13: 70 | F13: =VLOOKUP(D13,$A$61:$B$65,2,0) -> 39
A14: 12 | B14: Rocky 2 | C14: Acción | D14: PM13 | E14: 72 | F14: =VLOOKUP(D14,$A$61:$B$65,2,0) -> 39
... A56: 54 | B56: Copycat | C56: Suspenso | D56: PM13 | E56: 30 | F56: =VLOOKUP(D56,$A$61:$B$65,2,0) -> 39
A61: Categoría | B61: Precio Localidades
A62: ATP | B62: 35
A63: PM13 | B63: 39
A64: PM16 | B64: 42
A65: PM18 | B65: 45
A73: Cuenta de PELICULA | B73: CATEGORIA | I73: GENERO | J73: Promedio de LOCALIDADES VENDIDAS
A74: GENERO | B74: ATP | C74: PM13 | D74: PM16 | E74: PM18 | F74: Total general | I74: Acción | J74: 65.8
A75: Acción | C75: 5 | F75: 5 | I75: Aventuras | J75: 22
A76: Aventuras | E76: 1 | F76: 1 | I76: Belica | J76: 65
A77: Belica | B77: 1 | F77: 1 | I77: C.Ficción | J77: 48.333333
A78: C.Ficción | B78: 10 | C78: 3 | D78: 2 | F78: 15 | I78: Clásica | J78: 24.5
A79: Clásica | B79: 2 | F79: 2 | I79: Comedia | J79: 46.2
A80: Comedia | B80: 4 | D80: 1 | F80: 5 | I80: Drama | J80: 43.5
A81: Drama | B81: 2 | C81: 3 | D81: 3 | F81: 8 | I81: Erotica | J81: 33
A82: Erotica | E82: 3 | F82: 3 | I82: Infantil | J82: 53.5
A83: Infantil | B83: 4 | F83: 4 | I83: Suspenso | J83: 29.6
A84: Suspenso | B84: 1 | C84: 2 | E84: 2 | F84: 5 | I84: Terror | J84: 29
A85: Terror | E85: 2 | F85: 2 | I85: Testimonial | J85: 45.333333
A86: Testimonial | D86: 3 | F86: 3 | I86: Total general | J86: 44.888889
A87: Total general | B87: 24 | C87: 13 | D87: 9 | E87: 8 | F87: 54
A100: 41730

Sheet Ejercicio 2.3
C1: CINE POPULAR BARRIAL | M1: CTII-2024
A2: CODIGO | B2: PELICULA | C2: GENERO | D2: CATEGORIA | E2: LOCALIDADES VENDIDAS | F2: PRECIO LOCALIDADES
A3: 1 | B3: Lo que el viento se llevó | C3: Clásica | D3: ATP | E3: 22 | F3: =VLOOKUP(D3,$A$61:$B$65,2,0) -> 35
A4: 2 | B4: Casa Blanca | C4: Clásica | D4: ATP | E4: 27 | F4: =VLOOKUP(D4,$A$61:$B$65,2,0) -> 35
A5: 3 | B5: Blancanieves | C5: Infantil | D5: ATP | E5: 35 | F5: =VLOOKUP(D5,$A$61:$B$65,2,0) -> 35
A6: 5 | B6: La guerra de las galaxias | C6: C.Ficción | D6: ATP | E6: 45 | F6: =VLOOKUP(D6,$A$61:$B$65,2,0) -> 35
A7: 6 | B7: Robocop | C7: C.Ficción | D7: ATP | E7: 50 | F7: =VLOOKUP(D7,$A$61:$B$65,2,0) -> 35
A8: 7 | B8: Robocop 2 | C8: C.Ficción | D8: ATP | E8: 52 | F8: =VLOOKUP(D8,$A$61:$B$65,2,0) -> 35
A9: 8 | B9: Matrix | C9: C.Ficción | D9: ATP | E9: 70 | F9: =VLOOKUP(D9,$A$61:$B$65,2,0) -> 35
A10: 9 | B10: Matrix 2 | C10: C.Ficción | D10: ATP | E10: 70 | F10: =VLOOKUP(D10,$A$61:$B$65,2,0) -> 35
A11: 10 | B11: Matrix 3 | C11: C.Ficción | D11: ATP | E11: 55 | F11: =VLOOKUP(D11,$A$61:$B$65,2,0) -> 35
A12: 20 | B12: Fantasía | C12: C.Ficción | D12: ATP | E12: 45 | F12: =VLOOKUP(D12,$A$61:$B$65,2,0) -> 35
A13: 21 | B13: Gravedad | C13: C.Ficción | D13: ATP | E13: 45 | F13: =VLOOKUP(D13,$A$61:$B$65,2,0) -> 35
A14: 34 | B14: Terminator I | C14: C.Ficción | D14: ATP | E14: 45 | F14: =VLOOKUP(D14,$A$61:$B$65,2,0) -> 35
... A56: 33 | B56: Atracción fatal | C56: Suspenso | D56: PM18 | E56: 54 | F56: =VLOOKUP(D56,$A$61:$B$65,2,0) -> 45
A61: Categoría | B61: Precio Localidades
A62: ATP | B62: 35
A63: PM13 | B63: 39
A64: PM16 | B64: 42
A65: PM18 | B65: 45
A100: 41730

Sheet Ejercicio 3
A1: EMPRESA MAYORISTA BAIRES - Control de Stock
A4: Código | B4: Nombre | C4: Proveedor | D4: Categoría | E4: Cantidad por unidad | F4: Precio unitario | G4: Unidades en existencia | H4: Existencia crítica | I4: Nueva compra | J4: Total Bruto | K4: Costo Almacenamiento | L4: Total Neto
A5: 1 | B5: Té Dharamsala | C5: Exotic Liquids | D5: Bebidas | E5: 10 cajas x 20 bolsas | F5: 18 | G5: 39 | H5: =VLOOKUP(D5,$B$85:$D$93,2,0) -> 10 | I5: =IF(G5=0,H5*3,IF(G5<H5,(G5*H5)*1.1,0)) -> 0 | J5: =G5*F5 -> 702 | K5: =VLOOKUP(D5,$B$85:$D$93,3,0)*G5 -> 39 | L5: =J5+K5 -> 741
A6: 2 | B6: Cerveza tibetana Barley | C6: Exotic Liquids | D6: Bebidas | E6: 24 - bot. 12 l | F6: 19 | G6: 17 | H6: =VLOOKUP(D6,$B$85:$D$93,2,0) -> 10 | I6: =IF(G6=0,H6*3,IF(G6<H6,(G6*H6)*1.1,0)) -> 0 | J6: =G6*F6 -> 323 | K6: =VLOOKUP(D6,$B$85:$D$93,3,0)*G6 -> 17 | L6: =J6+K6 -> 340
A7: 24 | B7: Refresco Guaraná Fantástica | C7: Refrescos Americanas LTDA | D7: Bebidas | E7: 12 - latas 355 ml | F7: 4.5 | G7: 50 | H7: =VLOOKUP(D7,$B$85:$D$93,2,0) -> 10 | I7: =IF(G7=0,H7*3,IF(G7<H7,(G7*H7)*1.1,0)) -> 0 | J7: =G7*F7 -> 225 | K7: =VLOOKUP(D7,$B$85:$D$93,3,0)*G7 -> 50 | L7: =J7+K7 -> 275
A8: 34 | B8: Cerveza Sasquatch | C8: Bigfoot Breweries | D8: Bebidas | E8: 24 - bot. 12 l | F8: 14 | G8: 111 | H8: =VLOOKUP(D8,$B$85:$D$93,2,0) -> 10 | I8: =IF(G8=0,H8*3,IF(G8<H8,(G8*H8)*1.1,0)) -> 0 | J8: =G8*F8 -> 1554 | K8: =VLOOKUP(D8,$B$85:$D$93,3,0)*G8 -> 111 | L8: =J8+K8 -> 1665
A9: 35 | B9: Cerveza negra Steeleye | C9: Bigfoot Breweries | D9: Bebidas | E9: 24 - bot. 12 l | F9: 18 | G9: 20 | H9: =VLOOKUP(D9,$B$85:$D$93,2,0) -> 10 | I9: =IF(G9=0,H9*3,IF(G9<H9,(G9*H9)*1.1,0)) -> 0 | J9: =G9*F9 -> 360 | K9: =VLOOKUP(D9,$B$85:$D$93,3,0)*G9 -> 20 | L9: =J9+K9 -> 380
A10: 38 | B10: Vino Côte de Blaye | C10: Aux joyeux ecclésiastiques | D10: Bebidas | E10: 12 - bot. 75 cl | F10: 263.5 | G10: 17 | H10: =VLOOKUP(D10,$B$85:$D$93,2,0) -> 10 | I10: =IF(G10=0,H10*3,IF(G10<H10,(G10*H10)*1.1,0)) -> 0 | J10: =G10*F10 -> 4479.5 | K10: =VLOOKUP(D10,$B$85:$D$93,3,0)*G10 -> 17 | L10: =J10+K10 -> 4496.5
A11: 39 | B11: Licor verde Chartreuse | C11: Aux joyeux ecclésiastiques | D11: Bebidas | E11: 750 cc por bot. | F11: 18 | G11: 69 | H11: =VLOOKUP(D11,$B$85:$D$93,2,0) -> 10 | I11: =IF(G11=0,H11*3,IF(G11<H11,(G11*H11)*1.1,0)) -> 0 | J11: =G11*F11 -> 1242 | K11: =VLOOKUP(D11,$B$85:$D$93,3,0)*G11 -> 69 | L11: =J11+K11 -> 1311
A12: 43 | B12: Café de Malasia | C12: Leka Trading | D12: Bebidas | E12: 16 - latas 500 g | F12: 46 | G12: 17 | H12: =VLOOKUP(D12,$B$85:$D$93,2,0) -> 10 | I12: =IF(G12=0,H12*3,IF(G12<H12,(G12*H12)*1.1,0)) -> 0 | J12: =G12*F12 -> 782 | K12: =VLOOKUP(D12,$B$85:$D$93,3,0)*G12 -> 17 | L12: =J12+K12 -> 799
A13: 67 | B13: Cerveza Laughing Lumberjack | C13: Bigfoot Breweries | D13: Bebidas | E13: 24 - bot. 12 l | F13: 14 | G13: 52 | H13: =VLOOKUP(D13,$B$85:$D$93,2,0) -> 10 | I13: =IF(G13=0,H13*3,IF(G13<H13,(G13*H13)*1.1,0)) -> 0 | J13: =G13*F13 -> 728 | K13: =VLOOKUP(D13,$B$85:$D$93,3,0)*G13 -> 52 | L13: =J13+K13 -> 780
A14: 70 | B14: Cerveza Outback | C14: Pavlova, Ltd. | D14: Bebidas | E14: 24 - bot. 355 ml | F14: 15 | G14: 15 | H14: =VLOOKUP(D14,$B$85:$D$93,2,0) -> 10 | I14: =IF(G14=0,H14*3,IF(G14<H14,(G14*H14)*1.1,0)) -> 0 | J14: =G14*F14 -> 225 | K14: =VLOOKUP(D14,$B$85:$D$93,3,0)*G14 -> 15 | L14: =J14+K14 -> 240
A15: 75 | B15: Cerveza Klosterbier Rhönbräu | C15: Plusspar Lebensmittelgroßmärkte AG | D15: Bebidas | E15: 24 - bot. 0,5 l | F15: 7.75 | G15: 125 | H15: =VLOOKUP(D15,$B$85:$D$93,2,0) -> 10 | I15: =IF(G15=0,H15*3,IF(G15<H15,(G15*H15)*1.1,0)) -> 0 | J15: =G15*F15 -> 968.75 | K15: =VLOOKUP(D15,$B$85:$D$93,3,0)*G15 -> 125 | L15: =J15+K15 -> 1093.75
A16: 76 | B16: Licor Cloudberry | C16: Karkki Oy | D16: Bebidas | E16: 500 ml | F16: 18 | G16: 57 | H16: =VLOOKUP(D16,$B$85:$D$93,2,0) -> 10 | I16: =IF(G16=0,H16*3,IF(G16<H16,(G16*H16)*1.1,0)) -> 0 | J16: =G16*F16 -> 1026 | K16: =VLOOKUP(D16,$B$85:$D$93,3,0)*G16 -> 57 | L16: =J16+K16 -> 1083
... A81: 68 | B81: Barras de pan de Escocia | C81: Specialty Biscuits, Ltd. | D81: Repostería | E81: 10 cajas x 8 porc. | F81: 12.5 | G81: 6 | H81: =VLOOKUP(D81,$B$85:$D$93,2,0) -> 25 | I81: =IF(G81=0,H81*3,IF(G81<H81,(G81*H81)*1.1,0)) -> 165 | J81: =G81*F81 -> 75 | K81: =VLOOKUP(D81,$B$85:$D$93,3,0)*G81 -> 12 | L81: =J81+K81 -> 87
B85: Categoría | C85: Existencia crítica | D85: Costo Almacén (unitario)
B86: Bebidas | C86: 10 | D86: 1
B87: Carnes | C87: 20 | D87: 5
B88: Condimentos | C88: 15 | D88: 1
B89: Frutas/Verduras | C89: 10 | D89: 5
B90: Granos/Cereales | C90: 5 | D90: 3
B91: Lácteos | C91: 10 | D91: 5
B92: Pescado/Marisco | C92: 5 | D92: 5
B93: Repostería | C93: 25 | D93: 2
A100: 41730

Sheet Ejercicio 3.1
A1: EMPRESA MAYORISTA BAIRES - Control de Stock
A4: Código | B4: Nombre | C4: Proveedor | D4: Categoría | E4: Cantidad por unidad | F4: Precio unitario | G4: Unidades en existencia | H4: Existencia crítica | I4: Nueva compra | J4: Total Bruto | K4: Costo Almacenamiento | L4: Total Neto
A5: 1 | B5: Té Dharamsala | C5: Exotic Liquids | D5: Bebidas | E5: 10 cajas x 20 bolsas | F5: 18 | G5: 39 | H5: =VLOOKUP(D5,$B$85:$D$93,2,0) -> 10 | I5: =IF(G5=0,H5*3,IF(G5<H5,(G5*H5)*1.1,0)) -> 0 | J5: =G5*F5 -> 702 | K5: =VLOOKUP(D5,$B$85:$D$93,3,0)*G5 -> 39 | L5: =J5+K5 -> 741
A6: 2 | B6: Cerveza tibetana Barley | C6: Exotic Liquids | D6: Bebidas | E6: 24 - bot. 12 l | F6: 19 | G6: 17 | H6: =VLOOKUP(D6,$B$85:$D$93,2,0) -> 10 | I6: =IF(G6=0,H6*3,IF(G6<H6,(G6*H6)*1.1,0)) -> 0 | J6: =G6*F6 -> 323 | K6: =VLOOKUP(D6,$B$85:$D$93,3,0)*G6 -> 17 | L6: =J6+K6 -> 340
A7: 24 | B7: Refresco Guaraná Fantástica | C7: Refrescos Americanas LTDA | D7: Bebidas | E7: 12 - latas 355 ml | F7: 4.5 | G7: 50 | H7: =VLOOKUP(D7,$B$85:$D$93,2,0) -> 10 | I7: =IF(G7=0,H7*3,IF(G7<H7,(G7*H7)*1.1,0)) -> 0 | J7: =G7*F7 -> 225 | K7: =VLOOKUP(D7,$B$85:$D$93,3,0)*G7 -> 50 | L7: =J7+K7 -> 275
A8: 34 | B8: Cerveza Sasquatch | C8: Bigfoot Breweries | D8: Bebidas | E8: 24 - bot. 12 l | F8: 14 | G8: 111 | H8: =VLOOKUP(D8,$B$85:$D$93,2,0) -> 10 | I8: =IF(G8=0,H8*3,IF(G8<H8,(G8*H8)*1.1,0)) -> 0 | J8: =G8*F8 -> 1554 | K8: =VLOOKUP(D8,$B$85:$D$93,3,0)*G8 -> 111 | L8: =J8+K8 -> 1665
A9: 35 | B9: Cerveza negra Steeleye | C9: Bigfoot Breweries | D9: Bebidas | E9: 24 - bot. 12 l | F9: 18 | G9: 20 | H9: =VLOOKUP(D9,$B$85:$D$93,2,0) -> 10 | I9: =IF(G9=0,H9*3,IF(G9<H9,(G9*H9)*1.1,0)) -> 0 | J9: =G9*F9 -> 360 | K9: =VLOOKUP(D9,$B$85:$D$93,3,0)*G9 -> 20 | L9: =J9+K9 -> 380
A10: 38 | B10: Vino Côte de Blaye | C10: Aux joyeux ecclésiastiques | D10: Bebidas | E10: 12 - bot. 75 cl | F10: 263.5 | G10: 17 | H10: =VLOOKUP(D10,$B$85:$D$93,2,0) -> 10 | I10: =IF(G10=0,H10*3,IF(G10<H10,(G10*H10)*1.1,0)) -> 0 | J10: =G10*F10 -> 4479.5 | K10: =VLOOKUP(D10,$B$85:$D$93,3,0)*G10 -> 17 | L10: =J10+K10 -> 4496.5
A11: 39 | B11: Licor verde Chartreuse | C11: Aux joyeux ecclésiastiques | D11: Bebidas | E11: 750 cc por bot. | F11: 18 | G11: 69 | H11: =VLOOKUP(D11,$B$85:$D$93,2,0) -> 10 | I11: =IF(G11=0,H11*3,IF(G11<H11,(G11*H11)*1.1,0)) -> 0 | J11: =G11*F11 -> 1242 | K11: =VLOOKUP(D11,$B$85:$D$93,3,0)*G11 -> 69 | L11: =J11+K11 -> 1311
A12: 43 | B12: Café de Malasia | C12: Leka Trading | D12: Bebidas | E12: 16 - latas 500 g | F12: 46 | G12: 17 | H12: =VLOOKUP(D12,$B$85:$D$93,2,0) -> 10 | I12: =IF(G12=0,H12*3,IF(G12<H12,(G12*H12)*1.1,0)) -> 0 | J12: =G12*F12 -> 782 | K12: =VLOOKUP(D12,$B$85:$D$93,3,0)*G12 -> 17 | L12: =J12+K12 -> 799
A13: 67 | B13: Cerveza Laughing Lumberjack | C13: Bigfoot Breweries | D13: Bebidas | E13: 24 - bot. 12 l | F13: 14 | G13: 52 | H13: =VLOOKUP(D13,$B$85:$D$93,2,0) -> 10 | I13: =IF(G13=0,H13*3,IF(G13<H13,(G13*H13)*1.1,0)) -> 0 | J13: =G13*F13 -> 728 | K13: =VLOOKUP(D13,$B$85:$D$93,3,0)*G13 -> 52 | L13: =J13+K13 -> 780
A14: 70 | B14: Cerveza Outback | C14: Pavlova, Ltd. | D14: Bebidas | E14: 24 - bot. 355 ml | F14: 15 | G14: 15 | H14: =VLOOKUP(D14,$B$85:$D$93,2,0) -> 10 | I14: =IF(G14=0,H14*3,IF(G14<H14,(G14*H14)*1.1,0)) -> 0 | J14: =G14*F14 -> 225 | K14: =VLOOKUP(D14,$B$85:$D$93,3,0)*G14 -> 15 | L14: =J14+K14 -> 240
A15: 75 | B15: Cerveza Klosterbier Rhönbräu | C15: Plusspar Lebensmittelgroßmärkte AG | D15: Bebidas | E15: 24 - bot. 0,5 l | F15: 7.75 | G15: 125 | H15: =VLOOKUP(D15,$B$85:$D$93,2,0) -> 10 | I15: =IF(G15=0,H15*3,IF(G15<H15,(G15*H15)*1.1,0)) -> 0 | J15: =G15*F15 -> 968.75 | K15: =VLOOKUP(D15,$B$85:$D$93,3,0)*G15 -> 125 | L15: =J15+K15 -> 1093.75
A16: 76 | B16: Licor Cloudberry | C16: Karkki Oy | D16: Bebidas | E16: 500 ml | F16: 18 | G16: 57 | H16: =VLOOKUP(D16,$B$85:$D$93,2,0) -> 10 | I16: =IF(G16=0,H16*3,IF(G16<H16,(G16*H16)*1.1,0)) -> 0 | J16: =G16*F16 -> 1026 | K16: =VLOOKUP(D16,$B$85:$D$93,3,0)*G16 -> 57 | L16: =J16+K16 -> 1083
... A81: 68 | B81: Barras de pan de Escocia | C81: Specialty Biscuits, Ltd. | D81: Repostería | E81: 10 cajas x 8 porc. | F81: 12.5 | G81: 6 | H81: =VLOOKUP(D81,$B$85:$D$93,2,0) -> 25 | I81: =IF(G81=0,H81*3,IF(G81<H81,(G81*H81)*1.1,0)) -> 165 | J81: =G81*F81 -> 75 | K81: =VLOOKUP(D81,$B$85:$D$93,3,0)*G81 -> 12 | L81: =J81+K81 -> 87
B85: Categoría | C85: Existencia crítica | D85: Costo Almacén (unitario)
B86: Bebidas | C86: 10 | D86: 1
B87: Carnes | C87: 20 | D87: 5
B88: Condimentos | C88: 15 | D88: 1
B89: Frutas/Verduras | C89: 10 | D89: 5
B90: Granos/Cereales | C90: 5 | D90: 3
B91: Lácteos | C91: 10 | D91: 5
B92: Pescado/Marisco | C92: 5 | D92: 5
B93: Repostería | C93: 25 | D93: 2
B99: CÓDIGO | C99: NOMBRE | D99: CATEGORÍA
A100: 41730 | B100: 23 | C100: =DGET(A4:L81,B4,B99:B100) -> Pan fino | D100: =DGET(A4:L81,D4,B99:B100) -> Granos/Cereales
B101: =DCOUNT(A4:L81,G4,D99:D100) -> 7 | C101: Cantidad de productos de esa Categoría:
B102: =DSUM(A4:L81,L4,D99:D100) -> 6518.5 | C102: suma el importe total neto de esa categoria
B103: =DMAX(A4:L81,F4,D99:D100) -> 38 | C103: Precio Unitario más alto de esa Categoría:
B104: =DMIN(A4:L81,A4,D99:D100) -> 22 | C104: Código más bajo de un producto en esa Categoría:
B105: =DAVERAGE(A4:L81,J4,D99:D100) -> 799.21429 | C105: Promedio del Total Bruto de esa Categoría:

Sheet Ejercicio 3.2
A1: EMPRESA MAYORISTA BAIRES - Control de Stock
A4: Código | B4: Nombre | C4: Proveedor | D4: Categoría | E4: Cantidad por unidad | F4: Precio unitario | G4: Unidades en existencia | H4: Existencia crítica | I4: Nueva compra | J4: Total Bruto | K4: Costo Almacenamiento | L4: Total Neto
A5: 1 | B5: Té Dharamsala | C5: Exotic Liquids | D5: Bebidas | E5: 10 cajas x 20 bolsas | F5: 18 | G5: 39 | H5: =VLOOKUP(D5,$B$85:$D$93,2,0) -> 10 | I5: =IF(G5=0,H5*3,IF(G5<H5,(G5*H5)*1.1,0)) -> 0 | J5: =G5*F5 -> 702 | K5: =VLOOKUP(D5,$B$85:$D$93,3,0)*G5 -> 39 | L5: =J5+K5 -> 741
A6: 2 | B6: Cerveza tibetana Barley | C6: Exotic Liquids | D6: Bebidas | E6: 24 - bot. 12 l | F6: 19 | G6: 17 | H6: =VLOOKUP(D6,$B$85:$D$93,2,0) -> 10 | I6: =IF(G6=0,H6*3,IF(G6<H6,(G6*H6)*1.1,0)) -> 0 | J6: =G6*F6 -> 323 | K6: =VLOOKUP(D6,$B$85:$D$93,3,0)*G6 -> 17 | L6: =J6+K6 -> 340
A7: 24 | B7: Refresco Guaraná Fantástica | C7: Refrescos Americanas LTDA | D7: Bebidas | E7: 12 - latas 355 ml | F7: 4.5 | G7: 50 | H7: =VLOOKUP(D7,$B$85:$D$93,2,0) -> 10 | I7: =IF(G7=0,H7*3,IF(G7<H7,(G7*H7)*1.1,0)) -> 0 | J7: =G7*F7 -> 225 | K7: =VLOOKUP(D7,$B$85:$D$93,3,0)*G7 -> 50 | L7: =J7+K7 -> 275
A8: 34 | B8: Cerveza Sasquatch | C8: Bigfoot Breweries | D8: Bebidas | E8: 24 - bot. 12 l | F8: 14 | G8: 111 | H8: =VLOOKUP(D8,$B$85:$D$93,2,0) -> 10 | I8: =IF(G8=0,H8*3,IF(G8<H8,(G8*H8)*1.1,0)) -> 0 | J8: =G8*F8 -> 1554 | K8: =VLOOKUP(D8,$B$85:$D$93,3,0)*G8 -> 111 | L8: =J8+K8 -> 1665
A9: 35 | B9: Cerveza negra Steeleye | C9: Bigfoot Breweries | D9: Bebidas | E9: 24 - bot. 12 l | F9: 18 | G9: 20 | H9: =VLOOKUP(D9,$B$85:$D$93,2,0) -> 10 | I9: =IF(G9=0,H9*3,IF(G9<H9,(G9*H9)*1.1,0)) -> 0 | J9: =G9*F9 -> 360 | K9: =VLOOKUP(D9,$B$85:$D$93,3,0)*G9 -> 20 | L9: =J9+K9 -> 380
A10: 38 | B10: Vino Côte de Blaye | C10: Aux joyeux ecclésiastiques | D10: Bebidas | E10: 12 - bot. 75 cl | F10: 263.5 | G10: 17 | H10: =VLOOKUP(D10,$B$85:$D$93,2,0) -> 10 | I10: =IF(G10=0,H10*3,IF(G10<H10,(G10*H10)*1.1,0)) -> 0 | J10: =G10*F10 -> 4479.5 | K10: =VLOOKUP(D10,$B$85:$D$93,3,0)*G10 -> 17 | L10: =J10+K10 -> 4496.5
A11: 39 | B11: Licor verde Chartreuse | C11: Aux joyeux ecclésiastiques | D11: Bebidas | E11: 750 cc por bot. | F11: 18 | G11: 69 | H11: =VLOOKUP(D11,$B$85:$D$93,2,0) -> 10 | I11: =IF(G11=0,H11*3,IF(G11<H11,(G11*H11)*1.1,0)) -> 0 | J11: =G11*F11 -> 1242 | K11: =VLOOKUP(D11,$B$85:$D$93,3,0)*G11 -> 69 | L11: =J11+K11 -> 1311
A12: 43 | B12: Café de Malasia | C12: Leka Trading | D12: Bebidas | E12: 16 - latas 500 g | F12: 46 | G12: 17 | H12: =VLOOKUP(D12,$B$85:$D$93,2,0) -> 10 | I12: =IF(G12=0,H12*3,IF(G12<H12,(G12*H12)*1.1,0)) -> 0 | J12: =G12*F12 -> 782 | K12: =VLOOKUP(D12,$B$85:$D$93,3,0)*G12 -> 17 | L12: =J12+K12 -> 799
A13: 67 | B13: Cerveza Laughing Lumberjack | C13: Bigfoot Breweries | D13: Bebidas | E13: 24 - bot. 12 l | F13: 14 | G13: 52 | H13: =VLOOKUP(D13,$B$85:$D$93,2,0) -> 10 | I13: =IF(G13=0,H13*3,IF(G13<H13,(G13*H13)*1.1,0)) -> 0 | J13: =G13*F13 -> 728 | K13: =VLOOKUP(D13,$B$85:$D$93,3,0)*G13 -> 52 | L13: =J13+K13 -> 780
A14: 70 | B14: Cerveza Outback | C14: Pavlova, Ltd. | D14: Bebidas | E14: 24 - bot. 355 ml | F14: 15 | G14: 15 | H14: =VLOOKUP(D14,$B$85:$D$93,2,0) -> 10 | I14: =IF(G14=0,H14*3,IF(G14<H14,(G14*H14)*1.1,0)) -> 0 | J14: =G14*F14 -> 225 | K14: =VLOOKUP(D14,$B$85:$D$93,3,0)*G14 -> 15 | L14: =J14+K14 -> 240
A15: 75 | B15: Cerveza Klosterbier Rhönbräu | C15: Plusspar Lebensmittelgroßmärkte AG | D15: Bebidas | E15: 24 - bot. 0,5 l | F15: 7.75 | G15: 125 | H15: =VLOOKUP(D15,$B$85:$D$93,2,0) -> 10 | I15: =IF(G15=0,H15*3,IF(G15<H15,(G15*H15)*1.1,0)) -> 0 | J15: =G15*F15 -> 968.75 | K15: =VLOOKUP(D15,$B$85:$D$93,3,0)*G15 -> 125 | L15: =J15+K15 -> 1093.75
A16: 76 | B16: Licor Cloudberry | C16: Karkki Oy | D16: Bebidas | E16: 500 ml | F16: 18 | G16: 57 | H16: =VLOOKUP(D16,$B$85:$D$93,2,0) -> 10 | I16: =IF(G16=0,H16*3,IF(G16<H16,(G16*H16)*1.1,0)) -> 0 | J16: =G16*F16 -> 1026 | K16: =VLOOKUP(D16,$B$85:$D$93,3,0)*G16 -> 57 | L16: =J16+K16 -> 1083
... A81: 68 | B81: Barras de pan de Escocia | C81: Specialty Biscuits, Ltd. | D81: Repostería | E81: 10 cajas x 8 porc. | F81: 12.5 | G81: 6 | H81: =VLOOKUP(D81,$B$85:$D$93,2,0) -> 25 | I81: =IF(G81=0,H81*3,IF(G81<H81,(G81*H81)*1.1,0)) -> 165 | J81: =G81*F81 -> 75 | K81: =VLOOKUP(D81,$B$85:$D$93,3,0)*G81 -> 12 | L81: =J81+K81 -> 87
B85: Categoría | C85: Existencia crítica | D85: Costo Almacén (unitario)
B86: Bebidas | C86: 10 | D86: 1
B87: Carnes | C87: 20 | D87: 5
B88: Condimentos | C88: 15 | D88: 1
B89: Frutas/Verduras | C89: 10 | D89: 5
B90: Granos/Cereales | C90: 5 | D90: 3
B91: Lácteos | C91: 10 | D91: 5
B92: Pescado/Marisco | C92: 5 | D92: 5
B93: Repostería | C93: 25 | D93: 2
B99: Proveedor | C99: Suma de Total Neto
A100: 41730 | B100: Aux joyeux ecclésiastiques | C100: 5807.5
B101: Bigfoot Breweries | C101: 2825
B102: Cooperativa de Quesos 'Las Cabras' | C102: 4270
B103: Escargots Nouveaux | C103: 1131.5
B104: Exotic Liquids | C104: 1224
B105: Forêts d'érables | C105: 4205.6
B106: Formaggi Fortini s.r.l. | C106: 890.2
B107: Gai pâturage | C107: 5481
B108: G'day, Mate | C108: 1540
B109: Grandma Kelly's Homestead | C109: 3891
B110: Heli Süßwaren GmbH & Co. KG | C110: 3963.55
B111: Karkki Oy | C111: 2489.25
B112: Leka Trading | C112: 1793.15
... B129: Total general | C129: 83772.85

Sheet Ejercicio 3.3
A1: EMPRESA MAYORISTA BAIRES - Control de Stock
A4: Código | B4: Nombre | C4: Proveedor | D4: Categoría | E4: Cantidad por unidad | F4: Precio unitario | G4: Unidades en existencia | H4: Existencia crítica | I4: Nueva compra | J4: Total Bruto | K4: Costo Almacenamiento | L4: Total Neto
A5: 1 | B5: Té Dharamsala | C5: Exotic Liquids | D5: Bebidas | E5: 10 cajas x 20 bolsas | F5: 18 | G5: 39 | H5: =VLOOKUP(D5,$B$85:$D$93,2,0) -> 10 | I5: =IF(G5=0,H5*3,IF(G5<H5,(G5*H5)*1.1,0)) -> 0 | J5: =G5*F5 -> 702 | K5: =VLOOKUP(D5,$B$85:$D$93,3,0)*G5 -> 39 | L5: =J5+K5 -> 741
A6: 2 | B6: Cerveza tibetana Barley | C6: Exotic Liquids | D6: Bebidas | E6: 24 - bot. 12 l | F6: 19 | G6: 17 | H6: =VLOOKUP(D6,$B$85:$D$93,2,0) -> 10 | I6: =IF(G6=0,H6*3,IF(G6<H6,(G6*H6)*1.1,0)) -> 0 | J6: =G6*F6 -> 323 | K6: =VLOOKUP(D6,$B$85:$D$93,3,0)*G6 -> 17 | L6: =J6+K6 -> 340
A7: 24 | B7: Refresco Guaraná Fantástica | C7: Refrescos Americanas LTDA | D7: Bebidas | E7: 12 - latas 355 ml | F7: 4.5 | G7: 50 | H7: =VLOOKUP(D7,$B$85:$D$93,2,0) -> 10 | I7: =IF(G7=0,H7*3,IF(G7<H7,(G7*H7)*1.1,0)) -> 0 | J7: =G7*F7 -> 225 | K7: =VLOOKUP(D7,$B$85:$D$93,3,0)*G7 -> 50 | L7: =J7+K7 -> 275
A8: 34 | B8: Cerveza Sasquatch | C8: Bigfoot Breweries | D8: Bebidas | E8: 24 - bot. 12 l | F8: 14 | G8: 111 | H8: =VLOOKUP(D8,$B$85:$D$93,2,0) -> 10 | I8: =IF(G8=0,H8*3,IF(G8<H8,(G8*H8)*1.1,0)) -> 0 | J8: =G8*F8 -> 1554 | K8: =VLOOKUP(D8,$B$85:$D$93,3,0)*G8 -> 111 | L8: =J8+K8 -> 1665
A9: 35 | B9: Cerveza negra Steeleye | C9: Bigfoot Breweries | D9: Bebidas | E9: 24 - bot. 12 l | F9: 18 | G9: 20 | H9: =VLOOKUP(D9,$B$85:$D$93,2,0) -> 10 | I9: =IF(G9=0,H9*3,IF(G9<H9,(G9*H9)*1.1,0)) -> 0 | J9: =G9*F9 -> 360 | K9: =VLOOKUP(D9,$B$85:$D$93,3,0)*G9 -> 20 | L9: =J9+K9 -> 380
A10: 38 | B10: Vino Côte de Blaye | C10: Aux joyeux ecclésiastiques | D10: Bebidas | E10: 12 - bot. 75 cl | F10: 263.5 | G10: 17 | H10: =VLOOKUP(D10,$B$85:$D$93,2,0) -> 10 | I10: =IF(G10=0,H10*3,IF(G10<H10,(G10*H10)*1.1,0)) -> 0 | J10: =G10*F10 -> 4479.5 | K10: =VLOOKUP(D10,$B$85:$D$93,3,0)*G10 -> 17 | L10: =J10+K10 -> 4496.5
A11: 39 | B11: Licor verde Chartreuse | C11: Aux joyeux ecclésiastiques | D11: Bebidas | E11: 750 cc por bot. | F11: 18 | G11: 69 | H11: =VLOOKUP(D11,$B$85:$D$93,2,0) -> 10 | I11: =IF(G11=0,H11*3,IF(G11<H11,(G11*H11)*1.1,0)) -> 0 | J11: =G11*F11 -> 1242 | K11: =VLOOKUP(D11,$B$85:$D$93,3,0)*G11 -> 69 | L11: =J11+K11 -> 1311
A12: 43 | B12: Café de Malasia | C12: Leka Trading | D12: Bebidas | E12: 16 - latas 500 g | F12: 46 | G12: 17 | H12: =VLOOKUP(D12,$B$85:$D$93,2,0) -> 10 | I12: =IF(G12=0,H12*3,IF(G12<H12,(G12*H12)*1.1,0)) -> 0 | J12: =G12*F12 -> 782 | K12: =VLOOKUP(D12,$B$85:$D$93,3,0)*G12 -> 17 | L12: =J12+K12 -> 799
A13: 67 | B13: Cerveza Laughing Lumberjack | C13: Bigfoot Breweries | D13: Bebidas | E13: 24 - bot. 12 l | F13: 14 | G13: 52 | H13: =VLOOKUP(D13,$B$85:$D$93,2,0) -> 10 | I13: =IF(G13=0,H13*3,IF(G13<H13,(G13*H13)*1.1,0)) -> 0 | J13: =G13*F13 -> 728 | K13: =VLOOKUP(D13,$B$85:$D$93,3,0)*G13 -> 52 | L13: =J13+K13 -> 780
A14: 70 | B14: Cerveza Outback | C14: Pavlova, Ltd. | D14: Bebidas | E14: 24 - bot. 355 ml | F14: 15 | G14: 15 | H14: =VLOOKUP(D14,$B$85:$D$93,2,0) -> 10 | I14: =IF(G14=0,H14*3,IF(G14<H14,(G14*H14)*1.1,0)) -> 0 | J14: =G14*F14 -> 225 | K14: =VLOOKUP(D14,$B$85:$D$93,3,0)*G14 -> 15 | L14: =J14+K14 -> 240
A15: 75 | B15: Cerveza Klosterbier Rhönbräu | C15: Plusspar Lebensmittelgroßmärkte AG | D15: Bebidas | E15: 24 - bot. 0,5 l | F15: 7.75 | G15: 125 | H15: =VLOOKUP(D15,$B$85:$D$93,2,0) -> 10 | I15: =IF(G15=0,H15*3,IF(G15<H15,(G15*H15)*1.1,0)) -> 0 | J15: =G15*F15 -> 968.75 | K15: =VLOOKUP(D15,$B$85:$D$93,3,0)*G15 -> 125 | L15: =J15+K15 -> 1093.75
A16: 76 | B16: Licor Cloudberry | C16: Karkki Oy | D16: Bebidas | E16: 500 ml | F16: 18 | G16: 57 | H16: =VLOOKUP(D16,$B$85:$D$93,2,0) -> 10 | I16: =IF(G16=0,H16*3,IF(G16<H16,(G16*H16)*1.1,0)) -> 0 | J16: =G16*F16 -> 1026 | K16: =VLOOKUP(D16,$B$85:$D$93,3,0)*G16 -> 57 | L16: =J16+K16 -> 1083
... A81: 68 | B81: Barras de pan de Escocia | C81: Specialty Biscuits, Ltd. | D81: Repostería | E81: 10 cajas x 8 porc. | F81: 12.5 | G81: 6 | H81: =VLOOKUP(D81,$B$85:$D$93,2,0) -> 25 | I81: =IF(G81=0,H81*3,IF(G81<H81,(G81*H81)*1.1,0)) -> 165 | J81: =G81*F81 -> 75 | K81: =VLOOKUP(D81,$B$85:$D$93,3,0)*G81 -> 12 | L81: =J81+K81 -> 87
B85: Categoría | C85: Existencia crítica | D85: Costo Almacén (unitario)
B86: Bebidas | C86: 10 | D86: 1
B87: Carnes | C87: 20 | D87: 5
B88: Condimentos | C88: 15 | D88: 1
B89: Frutas/Verduras | C89: 10 | D89: 5
B90: Granos/Cereales | C90: 5 | D90: 3
B91: Lácteos | C91: 10 | D91: 5
B92: Pescado/Marisco | C92: 5 | D92: 5
B93: Repostería | C93: 25 | D93: 2
A100: 41730

Sheet Ejercicio 4
B3: TORNEOS DEPORTIVOS
B4: TRIATLON EN LAS UNIVERSIDADES NACIONALES
E6: MEDALLERO
A7: DEPORTE | B7: TIEMPOS PROMEDIO (en min) | C7: DEPORTISTAS | D7: UNIVERSIDADES NACIONALES | E7: EDAD | F7: ORO | G7: PLATA | H7: BRONCE
A8: NATACIÓN | B8: 210 | C8: DEPORTISTA 1 | D8: UNLAM | E8: 22 | F8: 8 | G8: 10 | H8: 5
A9: CICLISMO | B9: 550 | C9: DEPORTISTA 2 | D9: UBA | E9: 21 | F9: 0 | G9: 0 | H9: 0
A10: PEDESTRE | B10: 820 | C10: DEPORTISTA 3 | D10: UBA | E10: 20 | F10: 10 | G10: 3 | H10: 5
A11: NATACIÓN | B11: 240 | C11: DEPORTISTA 4 | D11: UNQ | E11: 22 | F11: 2 | G11: 7 | H11: 4
A12: PEDESTRE | B12: 345 | C12: DEPORTISTA 5 | D12: UNLP | E12: 19 | F12: 2 | G12: 6 | H12: 11
A13: PEDESTRE | B13: 670 | C13: DEPORTISTA 6 | D13: UNSAM | E13: 23 | F13: 1 | G13: 1 | H13: 2
A14: CICLISMO | B14: 543 | C14: DEPORTISTA 7 | D14: UTN | E14: 24 | F14: 7 | G14: 7 | H14: 9
A15: CICLISMO | B15: 769 | C15: DEPORTISTA 8 | D15: UNLAM | E15: 21 | F15: 1 | G15: 1 | H15: 0
A16: NATACIÓN | B16: 439 | C16: DEPORTISTA 9 | D16: UNLP | E16: 20 | F16: 0 | G16: 1 | H16: 0
A17: CICLISMO | B17: 197 | C17: DEPORTISTA 10 | D17: UNLAM | E17: 25 | F17: 0 | G17: 0 | H17: 0
A18: PEDESTRE | B18: 200 | C18: DEPORTISTA 11 | D18: UBA | E18: 22 | F18: 3 | G18: 2 | H18: 1
A19: NATACIÓN | B19: 850 | C19: DEPORTISTA 12 | D19: UNLP | E19: 21 | F19: 10 | G19: 11 | H19: 2
... A47: NATACIÓN | B47: 762 | C47: DEPORTISTA 40 | D47: UNLAM | E47: 24 | F47: 11 | G47: 3 | H47: 9
A53: Total de MEDALLAS DE ORO de UNLAM, obtenida por NATACIÓN, deportistas menores de 25 años | E53: =SUMIFS(F8:F47,D8:D47,"UNLAM",A8:A47,"NATACIÓN",E8:E47,"<25") -> 23
A54: PROMEDIO DE EDADES de deportistas de UBA, no categoría CICLISMO con más de una MEDALLA DE PLATA | E54: =AVERAGEIFS(E8:E47,D8:D47,"UBA",A8:A47,"<>CICLISMO",G8:G47,">1") -> 20.666667
A55: Cuántos deportistas de la UNLP en categoría PEDESTRE, obtuvieron MEDALLAS DE BRONCE | E55: =COUNTIFS(D8:D47,"UNLP",A8:A47,"PEDESTRE",H8:H47,">0") -> 3
E59: Tiempos | G59: ¿Quién es? | H59: ¿De dónde?
A60: MEJORES TIEMPOS LOGRADOS POR LOS PARTICIPANTES | D60: MENOR TIEMPO-1 | E60: =SMALL(B8:B47,1) -> 197 | F60: MIN | G60: =VLOOKUP(E60,B8:D47,2,1) -> DEPORTISTA 10 | H60: =VLOOKUP(E60,B8:D47,3,FALSE) -> UNLAM
D61: MENOR TIEMPO-2 | E61: =SMALL(B8:B47,2) -> 198 | F61: MIN | G61: =VLOOKUP(E61,B8:D47,2,0) -> DEPORTISTA 37 | H61: =VLOOKUP(E61,B8:D47,3,FALSE) -> UNSAM
D62: MENOR TIEMPO-3 | E62: =SMALL(B8:B47,3) -> 200 | F62: MIN | G62: =VLOOKUP(E62,B8:D47,2,FALSE) -> DEPORTISTA 11 | H62: =VLOOKUP(E62,B8:D47,3,FALSE) -> UBA
E64: Tiempos | G64: ¿Quién es? | H64: ¿De dónde?
A65: PEORES TIEMPOS LOGRADOS POR LOS PARTICIPANTES | D65: MAYOR TIEMPO-1 | E65: =LARGE(B8:B47,1) -> 855 | F65: MIN | G65: =VLOOKUP(E65,B13:D52,2,0) -> DEPORTISTA 36
D66: MAYOR TIEMPO-2 | E66: =LARGE(B8:B47,2) -> 852 | F66: MIN | G66: =VLOOKUP(E66,B13:D52,2,0) -> DEPORTISTA 26
D67: MAYOR TIEMPO-3 | E67: =LARGE(B8:B47,3) -> 850 | F67: MIN | G67: =VLOOKUP(E67,B13:D52,2,0) -> DEPORTISTA 12
U2017: CTN2-2C-17

Sheet Ejercicio 5
A1: Modelo | B1: Precio | C1: Cilindrada (cc)
A2: Honda CBR500R | B2: 6999 | C2: 471
A3: Yamaha YZF-R3 | B3: 5299 | C3: 321
A4: Kawasaki Ninja 400 | B4: 4999 | C4: 399
A5: Suzuki GSX250R | B5: 4499 | C5: 248
A6: Ducati Panigale V2 | B6: 16995 | C6: 955
A7: BMW S1000RR | B7: 16995 | C7: 999
A8: KTM RC 390 | B8: 5599 | C8: 373
A9: Triumph Daytona Moto2 765 | B9: 15500 | C9: 765
A10: Aprilia RS 660 | B10: 11299 | C10: 659
A11: MV Agusta F3 800 | B11: 15498 | C11: 798
A12: Harley-Davidson Street 750 | B12: 7599 | C12: 749
A13: Indian Scout Sixty | B13: 8999 | C13: 999
... A21: Bajaj Dominar 400 | B21: 1999 | C21: 373

Sheet Ejercicio 6
A1: Fecha de Operación | B1: Factura | C1: Producto | D1: Precio Unitario | E1: Cantidad | F1: Importe Total | G1: Sucursal
A2: 45627 | B2: 0001-00223123 | C2: Alfajor FANTOCHE Night 50g. | D2: 360.43 | E2: 50 | F2: =D2*E2 -> 18021.5 | G2: Buenos Aires
A3: 45628 | B3: 0001-00223124 | C3: Alfajor CHOCO ARROZ Limón 22g. | D3: 456.76 | E3: 10 | F3: =D3*E3 -> 4567.6 | G3: Buenos Aires
A4: 45628 | B4: 0001-00223125 | C4: Caramelos Masticables MISKY Surtido x800g. | D4: 4419.38 | E4: 10 | F4: =D4*E4 -> 44193.8 | G4: Buenos Aires
A5: 45629 | B5: 0002-00003321 | C5: Chocolate MECANO Dulce de Leche x19g. | D5: 476.84 | E5: 20 | F5: =D5*E5 -> 9536.8 | G5: Rosario
A6: 45629 | B6: 0002-00003322 | C6: Obleas NUGATON Chocolate | D6: 477.73 | E6: 20 | F6: =D6*E6 -> 9554.6 | G6: Rosario
A7: 45630 | B7: 0003-00000112 | C7: Chocolate HAMLET Bicolor x45g. | D7: 469.76 | E7: 15 | F7: =D7*E7 -> 7046.4 | G7: Santiago del Estero
A8: 45630 | B8: 0001-00223126 | C8: Chocolate HAMLET Leche y Cookies x48g. | D8: 469.76 | E8: 5 | F8: =D8*E8 -> 2348.8 | G8: Buenos Aires
A9: 45631 | B9: 0003-00000113 | C9: Alfajor CHOCO ARROZ Marroc 22g. | D9: 456.76 | E9: 30 | F9: =D9*E9 -> 13702.8 | G9: Santiago del Estero
A10: 45632 | B10: 0002-00003323 | C10: SNUKS Aritos Frutales x200g. | D10: 1578.14 | E10: 20 | F10: =D10*E10 -> 31562.8 | G10: Rosario
A11: 45632 | B11: 0001-00223127 | C11: Barra De Frutos Secos MUDRA Bienestar x35g. | D11: 723.75 | E11: 15 | F11: =D11*E11 -> 10856.25 | G11: Buenos Aires
A12: 45633 | B12: 0003-00000114 | C12: SNUKS Aritos Frutales x200g. | D12: 1578.14 | E12: 10 | F12: =D12*E12 -> 15781.4 | G12: Santiago del Estero
A13: 45633 | B13: 0002-00003324 | C13: Obleas NUGATON Chocolate | D13: 477.73 | E13: 20 | F13: =D13*E13 -> 9554.6 | G13: Rosario
... A26: 45640 | B26: 0001-00223132 | C26: SNUKS Aritos Frutales x200g. | D26: 1578.14 | E26: 30 | F26: =D26*E26 -> 47344.2 | G26: Buenos Aires
A40: Producto | B40: Cuenta de Factura | C40: Suma de Importe Total
A41: Alfajor CHOCO ARROZ Limón 22g. | B41: 2 | C41: 6851.4
A42: Obleas NUGATON Chocolate | B42: 1 | C42: 7165.95
A43: Total general | B43: 3 | C43: 14017.35
